Workbook

Sheet Global
B4: Global Flexible Electronics and Circuit Market | D4: Market Value (US$ Million) | Q4: Global Flexible Electronics and Circuit Market | S4: Market Y-o-Y Growth (%) | AD4: Global Flexible Electronics and Circuit Market | AF4: Market Share (%)
C5: 2019 | D5: 2020 | E5: 2021 | F5: 2022 | G5: 2023 | H5: 2024 | I5: 2025 | J5: 2026 | K5: 2027 | L5: 2028 | M5: 2029 | N5: 2030 | O5: CAGR (2023-2030) % | R5: 2020 | S5: 2021 | T5: 2022 | U5: 2023 | V5: 2024 | W5: 2025 | X5: 2026 | Y5: 2027 | Z5: 2028 | AA5: 2029 | AB5: 2030 | AE5: 2019 | AF5: 2020 | AG5: 2021 | AH5: 2022 | AI5: 2023 | AJ5: 2024 | AK5: 2025 | AL5: 2026 | AM5: 2027 | AN5: 2028 | AO5: 2029 | AP5: 2030
B7: By Type | C7: 27500 | D7: 28100 | E7: 28900 | F7: 29900 | G7: 31300 | H7: 33000 | I7: 35000 | J7: 37600 | K7: 40900 | L7: 44950 | M7: 49880 | N7: 55859 | O7: =((N7/H7)^(1/7)-1)*100% -> 0.078087905 | Q7: By Type | R7: =(D7/C7-1)*100 -> 2.1818182 | S7: =(E7/D7-1)*100 -> 2.8469751 | T7: =(F7/E7-1)*100 -> 3.4602076 | U7: =(G7/F7-1)*100 -> 4.6822742 | V7: =(H7/G7-1)*100 -> 5.4313099 | W7: =(I7/H7-1)*100 -> 6.0606061 | X7: =(J7/I7-1)*100 -> 7.4285714 | Y7: =(K7/J7-1)*100 -> 8.7765957 | ... AB7: =(N7/M7-1)*100 -> 11.986768 | AD7: By Type | AE7: 1 | AF7: 1 | AG7: 1 | AH7: 1 | AI7: 1 | AJ7: 1 | AK7: 1 | AL7: 1 | AM7: 1 | AN7: 1 | AO7: 1 | AP7: 1
B8: Flexible Electronics | C8: =C$7*AE8 -> 15125 | D8: =D$7*AF8 -> 15449.891 | E8: =E$7*AG8 -> 15884.491 | F8: =F$7*AH8 -> 16428.691 | G8: =G$7*AI8 -> 17192.236 | H8: =H$7*AJ8 -> 18120 | I8: =I$7*AK8 -> 19211.818 | J8: =J$7*AL8 -> 20632.145 | ... N8: =N$7*AP8 -> 30610.732 | O8: =((N8/H8)^(1/7)-1)*100% -> 0.077781659 | Q8: Flexible Electronics | R8: =(D8/C8-1)*100 -> 2.1480391 | S8: =(E8/D8-1)*100 -> 2.8129648 | T8: =(F8/E8-1)*100 -> 3.4259833 | U8: =(G8/F8-1)*100 -> 4.6476342 | V8: =(H8/G8-1)*100 -> 5.3964104 | W8: =(I8/H8-1)*100 -> 6.0254867 | X8: =(J8/I8-1)*100 -> 7.3929873 | Y8: =(K8/J8-1)*100 -> 8.7405531 | ... AB8: =(N8/M8-1)*100 -> 11.949625 | AC8: 0.01 | AD8: Flexible Electronics | AE8: 0.55 | AF8: 0.54981818 | AG8: 0.54963636 | AH8: 0.54945455 | AI8: 0.54927273 | AJ8: 0.54909091 | AK8: 0.54890909 | AL8: 0.54872727 | AM8: 0.54854545 | AN8: 0.54836364 | AO8: 0.54818182 | AP8: 0.548
B9: Flexible Displays | C9: =C7*AE9 -> 5500 | D9: =D7*AF9 -> 5609.2709 | E9: =E7*AG9 -> 5757.9309 | F9: =F7*AH9 -> 5945.7509 | G9: =G7*AI9 -> 6212.1964 | H9: =H7*AJ9 -> 6537 | I9: =I7*AK9 -> 6919.8182 | J9: =J7*AL9 -> 7419.5055 | ... N9: =N7*AP9 -> 10937.192 | O9: =((N9/H9)^(1/7)-1)*100% -> 0.076297868 | Q9: Flexible Displays | R9: =(D9/C9-1)*100 -> 1.9867438 | S9: =(E9/D9-1)*100 -> 2.6502553 | T9: =(F9/E9-1)*100 -> 3.2619356 | U9: =(G9/F9-1)*100 -> 4.4812751 | V9: =(H9/G9-1)*100 -> 5.2284831 | W9: =(I9/H9-1)*100 -> 5.8561753 | X9: =(J9/I9-1)*100 -> 7.2211041 | Y9: =(K9/J9-1)*100 -> 8.5661186 | ... AB9: =(N9/M9-1)*100 -> 11.768814 | AC9: 0.01 | AD9: Flexible Displays | AE9: 0.2 | AF9: 0.19961818 | AG9: 0.19923636 | AH9: 0.19885455 | AI9: 0.19847273 | AJ9: 0.19809091 | AK9: 0.19770909 | AL9: 0.19732727 | AM9: 0.19694545 | AN9: 0.19656364 | AO9: 0.19618182 | AP9: 0.1958
B10: Flexible Batteries | C10: =C7*AE10 -> 3025 | D10: =D7*AF10 -> 3092.7882 | E10: =E7*AG10 -> 3182.6782 | F10: =F7*AH10 -> 3294.7082 | G10: =G7*AI10 -> 3450.9673 | H10: =H7*AJ10 -> 3640.5 | I10: =I7*AK10 -> 3863.3636 | J10: =J7*AL10 -> 4152.7491 | ... N10: =N7*AP10 -> 6183.5913 | O10: =((N10/H10)^(1/7)-1)*100% -> 0.078620163 | Q10: Flexible Batteries | R10: =(D10/C10-1)*100 -> 2.2409316 | S10: =(E10/D10-1)*100 -> 2.9064389 | T10: =(F10/E10-1)*100 -> 3.5199915 | U10: =(G10/F10-1)*100 -> 4.7427293 | V10: =(H10/G10-1)*100 -> 5.4921624 | W10: =(I10/H10-1)*100 -> 6.1217865 | X10: =(J10/I10-1)*100 -> 7.4905052 | Y10: =(K10/J10-1)*100 -> 8.8392705 | ... AB10: =(N10/M10-1)*100 -> 12.051181 | AC10: 0.03 | AD10: Flexible Batteries | AE10: 0.11 | AF10: 0.11006364 | AG10: 0.11012727 | AH10: 0.11019091 | AI10: 0.11025455 | AJ10: 0.11031818 | AK10: 0.11038182 | AL10: 0.11044545 | AM10: 0.11050909 | AN10: 0.11057273 | AO10: 0.11063636 | AP10: 0.1107
B11: Flexible Sensors | C11: =C7*AE11 -> 3850 | D11: =D7*AF11 -> 3935.2773 | E11: =E7*AG11 -> 4048.6273 | F11: =F7*AH11 -> 4190.0773 | G11: =G7*AI11 -> 4387.6909 | H11: =H7*AJ11 -> 4627.5 | I11: =I7*AK11 -> 4909.5455 | J11: =J7*AL11 -> 5275.9636 | ... N11: =N7*AP11 -> 7848.1895 | O11: =((N11/H11)^(1/7)-1)*100% -> 0.078387194 | Q11: Flexible Sensors | R11: =(D11/C11-1)*100 -> 2.2149941 | S11: =(E11/D11-1)*100 -> 2.8803561 | T11: =(F11/E11-1)*100 -> 3.4937768 | U11: =(G11/F11-1)*100 -> 4.7162289 | V11: =(H11/G11-1)*100 -> 5.4654965 | W11: =(I11/H11-1)*100 -> 6.0949855 | X11: =(J11/I11-1)*100 -> 7.463383 | Y11: =(K11/J11-1)*100 -> 8.8118327 | ... AB11: =(N11/M11-1)*100 -> 12.02301 | AC11: 0.02 | AD11: Flexible Sensors | AE11: 0.14 | AF11: 0.14004545 | AG11: 0.14009091 | AH11: 0.14013636 | AI11: 0.14018182 | AJ11: 0.14022727 | AK11: 0.14027273 | AL11: 0.14031818 | AM11: 0.14036364 | AN11: 0.14040909 | AO11: 0.14045455 | AP11: 0.1405
B12: Flexible Memory | C12: =C7*AE12 -> 2750 | D12: =D7*AF12 -> 2812.5545 | E12: =E7*AG12 -> 2895.2545 | F12: =F7*AH12 -> 2998.1545 | G12: =G7*AI12 -> 3141.3818 | H12: =H7*AJ12 -> 3315 | I12: =I7*AK12 -> 3519.0909 | J12: =J7*AL12 -> 3783.9273 | ... N12: =N7*AP12 -> 5641.759 | O12: =((N12/H12)^(1/7)-1)*100% -> 0.078922233 | Q12: Flexible Memory | R12: =(D12/C12-1)*100 -> 2.2747107 | S12: =(E12/D12-1)*100 -> 2.9403874 | T12: =(F12/E12-1)*100 -> 3.5540916 | U12: =(G12/F12-1)*100 -> 4.7771811 | V12: =(H12/G12-1)*100 -> 5.5268093 | W12: =(I12/H12-1)*100 -> 6.1565885 | X12: =(J12/I12-1)*100 -> 7.525704 | Y12: =(K12/J12-1)*100 -> 8.8748583 | ... AB12: =(N12/M12-1)*100 -> 12.087657 | AC12: 0.04 | AD12: Flexible Memory | AE12: 0.1 | AF12: 0.10009091 | AG12: 0.10018182 | AH12: 0.10027273 | AI12: 0.10036364 | AJ12: 0.10045455 | AK12: 0.10054545 | AL12: 0.10063636 | AM12: 0.10072727 | AN12: 0.10081818 | AO12: 0.10090909 | AP12: 0.101
B13: Flexible Circuit | C13: =C7*AE13 -> 12375 | D13: =D7*AF13 -> 12650.109 | E13: › | F13: =F7*AH13 -> 13471.309 | G13: =G7*AI13 -> 14107.764 | H13: =H7*AJ13 -> 14880 | I13: =I7*AK13 -> 15788.182 | J13: =J7*AL13 -> 16967.855 | K13: =K7*AM13 -> 18464.491 | L13: =L7*AN13 -> 20301.055 | M13: =M7*AO13 -> 22536.691 | N13: =N7*AP13 -> 25248.268 | O13: =((N13/H13)^(1/7)-1)*100% -> 0.07846013 | Q13: Flexible Circuit | R13: =(D13/C13-1)*100 -> 2.2231038 | S13: =(E13/D13-1)*100 -> #VALUE! | T13: =(F13/E13-1)*100 -> #VALUE! | U13: =(G13/F13-1)*100 -> 4.7245189 | V13: =(H13/G13-1)*100 -> 5.4738397 | W13: =(I13/H13-1)*100 -> 6.1033724 | X13: =(J13/I13-1)*100 -> 7.4718719 | Y13: =(K13/J13-1)*100 -> 8.8204219 | ... AB13: =(N13/M13-1)*100 -> 12.031833 | AC13: 0.02 | AD13: Flexible Circuit | AE13: 0.45 | AF13: 0.45018182 | AG13: 0.45036364 | AH13: 0.45054545 | AI13: 0.45072727 | AJ13: 0.45090909 | AK13: 0.45109091 | AL13: 0.45127273 | AM13: 0.45145455 | AN13: 0.45163636 | AO13: 0.45181818 | AP13: 0.452
B14: Single Sided Flex Circuit | C14: =C7*AE14 -> 3025 | D14: =D7*AF14 -> 3093.0436 | E14: =E7*AG14 -> 3183.2036 | F14: =F7*AH14 -> 3295.5236 | G14: =G7*AI14 -> 3452.1055 | H14: =H7*AJ14 -> 3642 | I14: =I7*AK14 -> 3865.2727 | J14: =J7*AL14 -> 4155.1418 | ... N14: =N7*AP14 -> 6189.1772 | O14: =((N14/H14)^(1/7)-1)*100% -> 0.078695822 | Q14: Single Sided Flex Circuit | R14: =(D14/C14-1)*100 -> 2.2493764 | S14: =(E14/D14-1)*100 -> 2.9149282 | T14: =(F14/E14-1)*100 -> 3.5285207 | U14: =(G14/F14-1)*100 -> 4.7513487 | V14: =(H14/G14-1)*100 -> 5.5008327 | W14: =(I14/H14-1)*100 -> 6.1304977 | X14: =(J14/I14-1)*100 -> 7.4993179 | Y14: =(K14/J14-1)*100 -> 8.8481828 | ... AB14: =(N14/M14-1)*100 -> 12.060323 | AC14: 0.02 | AD14: Single Sided Flex Circuit | AE14: 0.11 | AF14: 0.11007273 | AG14: 0.11014545 | AH14: 0.11021818 | AI14: 0.11029091 | AJ14: 0.11036364 | AK14: 0.11043636 | AL14: 0.11050909 | AM14: 0.11058182 | AN14: 0.11065455 | AO14: 0.11072727 | AP14: 0.1108
B15: Double Sided Flex Circuit | C15: =C7*AE15 -> 2475 | D15: =D7*AF15 -> 2532.8318 | E15: =E7*AG15 -> 2608.8818 | F15: =F7*AH15 -> 2703.2318 | G15: =G7*AI15 -> 2834.0727 | H15: =H7*AJ15 -> 2992.5 | I15: =I7*AK15 -> 3178.6364 | J15: =J7*AL15 -> 3419.8909 | ... N15: =N7*AP15 -> 5111.0985 | O15: =((N15/H15)^(1/7)-1)*100% -> 0.079472149 | Q15: Double Sided Flex Circuit | R15: =(D15/C15-1)*100 -> 2.3366391 | S15: =(E15/D15-1)*100 -> 3.0025681 | T15: =(F15/E15-1)*100 -> 3.6164919 | U15: =(G15/F15-1)*100 -> 4.8401661 | V15: =(H15/G15-1)*100 -> 5.590092 | W15: =(I15/H15-1)*100 -> 6.2200957 | X15: =(J15/I15-1)*100 -> 7.5898756 | Y15: =(K15/J15-1)*100 -> 8.9396791 | ... AB15: =(N15/M15-1)*100 -> 12.153913 | AC15: 0.03 | AD15: Double Sided Flex Circuit | AE15: 0.09 | AF15: 0.090136364 | AG15: 0.090272727 | AH15: 0.090409091 | AI15: 0.090545455 | AJ15: 0.090681818 | AK15: 0.090818182 | AL15: 0.090954545 | AM15: 0.091090909 | AN15: 0.091227273 | AO15: 0.091363636 | AP15: 0.0915
B16: Multilayer Flex Circuit | C16: =C7*AE16 -> 3575 | D16: =D7*AF16 -> 3648.4018 | E16: =E7*AG16 -> 3747.5418 | F16: =F7*AH16 -> 3872.3218 | G16: =G7*AI16 -> 4048.5127 | H16: =H7*AJ16 -> 4263 | I16: =I7*AK16 -> 4515.6364 | J16: =J7*AL16 -> 4844.9309 | ... N16: =N7*AP16 -> 7161.1238 | O16: =((N16/H16)^(1/7)-1)*100% -> 0.076913536 | Q16: Multilayer Flex Circuit | R16: =(D16/C16-1)*100 -> 2.0531977 | S16: =(E16/D16-1)*100 -> 2.7173542 | T16: =(F16/E16-1)*100 -> 3.3296493 | U16: =(G16/F16-1)*100 -> 4.5500069 | V16: =(H16/G16-1)*100 -> 5.2979276 | W16: =(I16/H16-1)*100 -> 5.9262577 | X16: =(J16/I16-1)*100 -> 7.2923176 | Y16: =(K16/J16-1)*100 -> 8.638457 | ... AB16: =(N16/M16-1)*100 -> 11.844009 | AC16: 0.01 | AD16: Multilayer Flex Circuit | AE16: 0.13 | AF16: 0.12983636 | AG16: 0.12967273 | AH16: 0.12950909 | AI16: 0.12934545 | AJ16: 0.12918182 | AK16: 0.12901818 | AL16: 0.12885455 | AM16: 0.12869091 | AN16: 0.12852727 | AO16: 0.12836364 | AP16: 0.1282
B17: Rigid Flex Circuit | C17: =C7*AE17 -> 1925 | D17: =D7*AF17 -> 1968.2773 | E17: =E7*AG17 -> 2025.6273 | F17: =F7*AH17 -> 2097.0773 | G17: =G7*AI17 -> 2196.6909 | H17: =H7*AJ17 -> 2317.5 | I17: =I7*AK17 -> 2459.5455 | J17: =J7*AL17 -> 2643.9636 | ... N17: =N7*AP17 -> 3938.0595 | O17: =((N17/H17)^(1/7)-1)*100% -> 0.078685019 | Q17: Rigid Flex Circuit | R17: =(D17/C17-1)*100 -> 2.24817 | S17: =(E17/D17-1)*100 -> 2.9137155 | T17: =(F17/E17-1)*100 -> 3.5273024 | U17: =(G17/F17-1)*100 -> 4.7501176 | V17: =(H17/G17-1)*100 -> 5.4995944 | W17: =(I17/H17-1)*100 -> 6.1292537 | X17: =(J17/I17-1)*100 -> 7.4980595 | Y17: =(K17/J17-1)*100 -> 8.8469103 | ... AB17: =(N17/M17-1)*100 -> 12.059018 | AC17: 0.04 | AD17: Rigid Flex Circuit | AE17: 0.07 | AF17: 0.070045455 | AG17: 0.070090909 | AH17: 0.070136364 | AI17: 0.070181818 | AJ17: 0.070227273 | AK17: 0.070272727 | AL17: 0.070318182 | AM17: 0.070363636 | AN17: 0.070409091 | AO17: 0.070454545 | AP17: 0.0705
B18: Others | C18: =C7*AE18 -> 1375 | D18: =D7*AF18 -> 1407.5545 | E18: =E7*AG18 -> 1450.2545 | F18: =F7*AH18 -> 1503.1545 | G18: =G7*AI18 -> 1576.3818 | H18: =H7*AJ18 -> 1665 | I18: =I7*AK18 -> 1769.0909 | J18: =J7*AL18 -> 1903.9273 | ... N18: =N7*AP18 -> 2848.809 | O18: =((N18/H18)^(1/7)-1)*100% -> 0.079745243 | Q18: Others | R18: =(D18/C18-1)*100 -> 2.3676033 | S18: =(E18/D18-1)*100 -> 3.0336302 | T18: =(F18/E18-1)*100 -> 3.6476355 | U18: =(G18/F18-1)*100 -> 4.8715731 | V18: =(H18/G18-1)*100 -> 5.6216191 | W18: =(I18/H18-1)*100 -> 6.2517063 | X18: =(J18/I18-1)*100 -> 7.6217883 | Y18: =(K18/J18-1)*100 -> 8.9718859 | ... AB18: =(N18/M18-1)*100 -> 12.186745 | AC18: 0.05 | AD18: Others | AE18: 0.05 | AF18: 0.050090909 | AG18: 0.050181818 | AH18: 0.050272727 | AI18: 0.050363636 | AJ18: 0.050454545 | AK18: 0.050545455 | AL18: 0.050636364 | AM18: 0.050727273 | AN18: 0.050818182 | AO18: 0.050909091 | AP18: 0.051
B20: By Vertical | C20: =C7 -> 27500 | D20: =D7 -> 28100 | E20: =E7 -> 28900 | F20: =F7 -> 29900 | G20: =G7 -> 31300 | H20: =H7 -> 33000 | I20: =I7 -> 35000 | J20: =J7 -> 37600 | ... N20: =N7 -> 55859 | O20: =((N20/H20)^(1/7)-1)*100% -> 0.078087905 | Q20: By Vertical | R20: =(D20/C20-1)*100 -> 2.1818182 | S20: =(E20/D20-1)*100 -> 2.8469751 | T20: =(F20/E20-1)*100 -> 3.4602076 | U20: =(G20/F20-1)*100 -> 4.6822742 | V20: =(H20/G20-1)*100 -> 5.4313099 | W20: =(I20/H20-1)*100 -> 6.0606061 | X20: =(J20/I20-1)*100 -> 7.4285714 | Y20: =(K20/J20-1)*100 -> 8.7765957 | ... AB20: =(N20/M20-1)*100 -> 11.986768 | AD20: By Vertical | AE20: 1 | AF20: 1 | AG20: 1 | AH20: 1 | AI20: 1 | AJ20: 1 | AK20: 1 | AL20: 1 | AM20: 1 | AN20: 1 | AO20: 1 | AP20: 1
B21: Automotive | C21: =C20*AE21 -> 4578.75 | D21: =D20*AF21 -> 4679.9273 | E21: =E20*AG21 -> 4814.4773 | F21: =F20*AH21 -> 4982.4273 | G21: =G20*AI21 -> 5217.1409 | H21: =H20*AJ21 -> 5502 | I21: =I20*AK21 -> 5837.0455 | J21: =J20*AL21 -> 6272.3636 | ... N21: =N20*AP21 -> 9328.453 | O21: =((N21/H21)^(1/7)-1)*100% -> 0.078339658 | Q21: Automotive | R21: =(D21/C21-1)*100 -> 2.2097138 | S21: =(E21/D21-1)*100 -> 2.8750447 | T21: =(F21/E21-1)*100 -> 3.4884369 | U21: =(G21/F21-1)*100 -> 4.7108292 | V21: =(H21/G21-1)*100 -> 5.4600613 | W21: =(I21/H21-1)*100 -> 6.0895212 | X21: =(J21/I21-1)*100 -> 7.4578515 | Y21: =(K21/J21-1)*100 -> 8.8062351 | ... AB21: =(N21/M21-1)*100 -> 12.017257 | AC21: 0.03 | AD21: Automotive | AE21: 0.1665 | AF21: 0.16654545 | AG21: 0.16659091 | AH21: 0.16663636 | AI21: 0.16668182 | AJ21: 0.16672727 | AK21: 0.16677273 | AL21: 0.16681818 | AM21: 0.16686364 | AN21: 0.16690909 | AO21: 0.16695455 | AP21: 0.167
B22: Military, Defense and Aerospace | C22: =C20*AE22 -> 3448.5 | D22: =D20*AF22 -> 3526.55 | E22: =E20*AG22 -> 3629.84 | F22: =F20*AH22 -> 3758.43 | G22: =G20*AI22 -> 3937.54 | H22: =H20*AJ22 -> 4154.7 | I22: =I20*AK22 -> 4410 | J22: =J20*AL22 -> 4741.36 | ... N22: =N20*AP22 -> 7066.1635 | O22: =((N22/H22)^(1/7)-1)*100% -> 0.078820386 | Q22: Military, Defense and Aerospace | R22: =(D22/C22-1)*100 -> 2.2633029 | S22: =(E22/D22-1)*100 -> 2.9289249 | T22: =(F22/E22-1)*100 -> 3.5425804 | U22: =(G22/F22-1)*100 -> 4.7655537 | V22: =(H22/G22-1)*100 -> 5.5151186 | W22: =(I22/H22-1)*100 -> 6.144848 | X22: =(J22/I22-1)*100 -> 7.5138322 | Y22: =(K22/J22-1)*100 -> 8.8628579 | ... AB22: =(N22/M22-1)*100 -> 12.075365 | AC22: 0.04 | AD22: Military, Defense and Aerospace | AE22: 0.1254 | AF22: 0.1255 | AG22: 0.1256 | AH22: 0.1257 | AI22: 0.1258 | AJ22: 0.1259 | AK22: 0.126 | AL22: 0.1261 | AM22: 0.1262 | AN22: 0.1263 | AO22: 0.1264 | AP22: 0.1265
B23: Consumer Electronics | C23: =C20*AE23 -> 6696.25 | D23: =D20*AF23 -> 6837.7518 | E23: =E20*AG23 -> 7027.6918 | F23: =F20*AH23 -> 7265.9718 | G23: =G20*AI23 -> 7601.0627 | H23: =H20*AJ23 -> 8008.5 | I23: =I20*AK23 -> 8488.1364 | J23: =J20*AL23 -> 9112.5309 | ... N23: =N20*AP23 -> 13501.12 | O23: =((N23/H23)^(1/7)-1)*100% -> 0.077463733 | Q23: Consumer Electronics | R23: =(D23/C23-1)*100 -> 2.1131502 | S23: =(E23/D23-1)*100 -> 2.7778136 | T23: =(F23/E23-1)*100 -> 3.3905869 | U23: =(G23/F23-1)*100 -> 4.6117838 | V23: =(H23/G23-1)*100 -> 5.3602672 | W23: =(I23/H23-1)*100 -> 5.9890911 | X23: =(J23/I23-1)*100 -> 7.3560852 | Y23: =(K23/J23-1)*100 -> 8.7031504 | ... AB23: =(N23/M23-1)*100 -> 11.911002 | AC23: 0.01 | AD23: Consumer Electronics | AE23: 0.2435 | AF23: 0.24333636 | AG23: 0.24317273 | AH23: 0.24300909 | AI23: 0.24284545 | AJ23: 0.24268182 | AK23: 0.24251818 | AL23: 0.24235455 | AM23: 0.24219091 | AN23: 0.24202727 | AO23: 0.24186364 | AP23: 0.2417
B24: Industrial | C24: =C20*AE24 -> 3165.25 | D24: =D20*AF24 -> 3235.8427 | E24: =E20*AG24 -> 3329.5427 | F24: =F20*AH24 -> 3446.3827 | G24: =G20*AI24 -> 3609.4591 | H24: =H20*AJ24 -> 3807.3 | I24: =I20*AK24 -> 4039.9545 | J24: =J20*AL24 -> 4342.1164 | ... N24: =N20*AP24 -> 6462.8863 | O24: =((N24/H24)^(1/7)-1)*100% -> 0.078524256 | Q24: Industrial | R24: =(D24/C24-1)*100 -> 2.2302418 | S24: =(E24/D24-1)*100 -> 2.8956908 | T24: =(F24/E24-1)*100 -> 3.5091906 | U24: =(G24/F24-1)*100 -> 4.7318124 | V24: =(H24/G24-1)*100 -> 5.4811789 | W24: =(I24/H24-1)*100 -> 6.110749 | X24: =(J24/I24-1)*100 -> 7.4793371 | Y24: =(K24/J24-1)*100 -> 8.8279741 | ... AB24: =(N24/M24-1)*100 -> 12.039588 | AC24: 0.05 | AD24: Industrial | AE24: 0.1151 | AF24: 0.11515455 | AG24: 0.11520909 | AH24: 0.11526364 | AI24: 0.11531818 | AJ24: 0.11537273 | AK24: 0.11542727 | AL24: 0.11548182 | AM24: 0.11553636 | AN24: 0.11559091 | AO24: 0.11564545 | AP24: 0.1157
B25: Healthcare and Medical | C25: =C20*AE25 -> 4983 | D25: =D20*AF25 -> 5086.1 | E25: =E20*AG25 -> 5225.12 | F25: =F20*AH25 -> 5399.94 | G25: =G20*AI25 -> 5646.52 | H25: =H20*AJ25 -> 5946.6 | I25: =I20*AK25 -> 6300 | J25: =J20*AL25 -> 6760.48 | ... N25: =N20*AP25 -> 9998.761 | O25: =((N25/H25)^(1/7)-1)*100% -> 0.077059355 | Q25: Healthcare and Medical | R25: =(D25/C25-1)*100 -> 2.0690347 | S25: =(E25/D25-1)*100 -> 2.733332 | T25: =(F25/E25-1)*100 -> 3.3457605 | U25: =(G25/F25-1)*100 -> 4.566347 | V25: =(H25/G25-1)*100 -> 5.3144238 | W25: =(I25/H25-1)*100 -> 5.9428917 | X25: =(J25/I25-1)*100 -> 7.3092063 | Y25: =(K25/J25-1)*100 -> 8.6555984 | ... AB25: =(N25/M25-1)*100 -> 11.861783 | AC25: 0.02 | AD25: Healthcare and Medical | AE25: 0.1812 | AF25: 0.181 | AG25: 0.1808 | AH25: 0.1806 | AI25: 0.1804 | AJ25: 0.1802 | AK25: 0.18 | AL25: 0.1798 | AM25: 0.1796 | AN25: 0.1794 | AO25: 0.1792 | AP25: 0.179
B26: Energy and Power | C26: =C20*AE26 -> 2433.75 | D26: =D20*AF26 -> 2488.3827 | E26: =E20*AG26 -> 2560.8027 | F26: =F20*AH26 -> 2651.0427 | G26: =G20*AI26 -> 2776.8791 | H26: =H20*AJ26 -> 2929.5 | I26: =I20*AK26 -> 3108.9545 | J26: =J20*AL26 -> 3341.9564 | ... N26: =N20*AP26 -> 4977.0369 | O26: =((N26/H26)^(1/7)-1)*100% -> 0.078654798 | Q26: Energy and Power | R26: =(D26/C26-1)*100 -> 2.2447962 | S26: =(E26/D26-1)*100 -> 2.910324 | T26: =(F26/E26-1)*100 -> 3.523895 | U26: =(G26/F26-1)*100 -> 4.7466743 | V26: =(H26/G26-1)*100 -> 5.4961309 | W26: =(I26/H26-1)*100 -> 6.1257739 | X26: =(J26/I26-1)*100 -> 7.4945392 | Y26: =(K26/J26-1)*100 -> 8.8433503 | ... AB26: =(N26/M26-1)*100 -> 12.055367 | AC26: 0.06 | AD26: Energy and Power | AE26: 0.0885 | AF26: 0.088554545 | AG26: 0.088609091 | AH26: 0.088663636 | AI26: 0.088718182 | AJ26: 0.088772727 | AK26: 0.088827273 | AL26: 0.088881818 | AM26: 0.088936364 | AN26: 0.088990909 | AO26: 0.089045455 | AP26: 0.0891
B27: Others | C27: =C20*AE27 -> 2194.5 | D27: =D20*AF27 -> 2245.4455 | E27: =E20*AG27 -> 2312.5255 | F27: =F20*AH27 -> 2395.8055 | G27: =G20*AI27 -> 2511.3982 | H27: =H20*AJ27 -> 2651.4 | I27: =I20*AK27 -> 2815.9091 | J27: =J20*AL27 -> 3029.1927 | ... N27: =N20*AP27 -> 4524.579 | O27: =((N27/H27)^(1/7)-1)*100% -> 0.079338231 | Q27: Others | R27: =(D27/C27-1)*100 -> 2.3215062 | S27: =(E27/D27-1)*100 -> 2.9873805 | T27: =(F27/E27-1)*100 -> 3.6012577 | U27: =(G27/F27-1)*100 -> 4.8247961 | V27: =(H27/G27-1)*100 -> 5.5746563 | W27: =(I27/H27-1)*100 -> 6.2046123 | X27: =(J27/I27-1)*100 -> 7.5742373 | Y27: =(K27/J27-1)*100 -> 8.9238897 | ... AB27: =(N27/M27-1)*100 -> 12.137796 | AC27: 0.07 | AD27: Others | AE27: 0.0798 | AF27: 0.079909091 | AG27: 0.080018182 | AH27: 0.080127273 | AI27: 0.080236364 | AJ27: 0.080345455 | AK27: 0.080454545 | AL27: 0.080563636 | AM27: 0.080672727 | AN27: 0.080781818 | AO27: 0.080890909 | AP27: 0.081
B29: By Region | C29: =C7 -> 27500 | D29: =D7 -> 28100 | E29: =E7 -> 28900 | F29: =F7 -> 29900 | G29: =G7 -> 31300 | H29: =H7 -> 33000 | I29: =I7 -> 35000 | J29: =J7 -> 37600 | ... N29: =N7 -> 55859 | O29: =((N29/H29)^(1/7)-1)*100% -> 0.078087905 | Q29: By Region | R29: =(D29/C29-1)*100 -> 2.1818182 | S29: =(E29/D29-1)*100 -> 2.8469751 | T29: =(F29/E29-1)*100 -> 3.4602076 | U29: =(G29/F29-1)*100 -> 4.6822742 | V29: =(H29/G29-1)*100 -> 5.4313099 | W29: =(I29/H29-1)*100 -> 6.0606061 | X29: =(J29/I29-1)*100 -> 7.4285714 | Y29: =(K29/J29-1)*100 -> 8.7765957 | ... AB29: =(N29/M29-1)*100 -> 11.986768 | AD29: By Region | AE29: 1 | AF29: 1 | AG29: 1 | AH29: 1 | AI29: 1 | AJ29: 1 | AK29: 1 | AL29: 1 | AM29: 1 | AN29: 1 | AO29: 1 | AP29: 1
B30: North America | C30: =C29*AE30 -> 8525 | D30: =D29*AF30 -> 8696.95 | E30: =E29*AG30 -> 8930.1 | F30: =F29*AH30 -> 9224.15 | G30: =G29*AI30 -> 9640.4 | H30: =H29*AJ30 -> 10147.5 | I30: =I29*AK30 -> 10745 | J30: =J29*AL30 -> 11524.4 | ... N30: =N29*AP30 -> 17009.066 | O30: =((N30/H30)^(1/7)-1)*100% -> 0.076579023 | Q30: North America | R30: =(D30/C30-1)*100 -> 2.0170088 | S30: =(E30/D30-1)*100 -> 2.6808249 | T30: =(F30/E30-1)*100 -> 3.2927963 | U30: =(G30/F30-1)*100 -> 4.5126109 | V30: =(H30/G30-1)*100 -> 5.2601552 | W30: =(I30/H30-1)*100 -> 5.8881498 | X30: =(J30/I30-1)*100 -> 7.2536063 | Y30: =(K30/J30-1)*100 -> 8.5991462 | ... AB30: =(N30/M30-1)*100 -> 11.803183 | AC30: 0.01 | AD30: North America | AE30: 0.31 | AF30: 0.3095 | AG30: 0.309 | AH30: 0.3085 | AI30: 0.308 | AJ30: 0.3075 | AK30: 0.307 | AL30: 0.3065 | AM30: 0.306 | AN30: 0.3055 | AO30: 0.305 | AP30: 0.3045
B31: Europe | C31: =C29*AE31 -> 6490 | D31: =D29*AF31 -> 6622.6591 | E31: =E29*AG31 -> 6802.0091 | F31: =F29*AH31 -> 7027.8591 | G31: =G29*AI31 -> 7346.9636 | H31: =H29*AJ31 -> 7735.5 | I31: =I29*AK31 -> 8193.1818 | J31: =J29*AL31 -> 8789.8545 | ... N31: =N29*AP31 -> 12987.218 | O31: =((N31/H31)^(1/7)-1)*100% -> 0.076829185 | Q31: Europe | R31: =(D31/C31-1)*100 -> 2.0440538 | S31: =(E31/D31-1)*100 -> 2.7081267 | T31: =(F31/E31-1)*100 -> 3.3203425 | U31: =(G31/F31-1)*100 -> 4.5405655 | V31: =(H31/G31-1)*100 -> 5.2883937 | W31: =(I31/H31-1)*100 -> 5.9166417 | X31: =(J31/I31-1)*100 -> 7.282552 | Y31: =(K31/J31-1)*100 -> 8.6285428 | ... AB31: =(N31/M31-1)*100 -> 11.833721 | AC31: 0.02 | AD31: Europe | AE31: 0.236 | AF31: 0.23568182 | AG31: 0.23536364 | AH31: 0.23504545 | AI31: 0.23472727 | AJ31: 0.23440909 | AK31: 0.23409091 | AL31: 0.23377273 | AM31: 0.23345455 | AN31: 0.23313636 | AO31: 0.23281818 | AP31: 0.2325
B32: Asia-Pacific | C32: =C29*AE32 -> 5720 | D32: =D29*AF32 -> 5849.9091 | E32: =E29*AG32 -> 6021.7091 | F32: =F29*AH32 -> 6235.5091 | G32: =G29*AI32 -> 6533.1636 | H32: =H29*AJ32 -> 6894 | I32: =I29*AK32 -> 7318.1818 | J32: =J29*AL32 -> 7868.6545 | ... N32: =N29*AP32 -> 11730.39 | O32: =((N32/H32)^(1/7)-1)*100% -> 0.078890354 | Q32: Asia-Pacific | R32: =(D32/C32-1)*100 -> 2.271138 | S32: =(E32/D32-1)*100 -> 2.9367978 | T32: =(F32/E32-1)*100 -> 3.550487 | U32: =(G32/F32-1)*100 -> 4.7735404 | V32: =(H32/G32-1)*100 -> 5.523149 | W32: =(I32/H32-1)*100 -> 6.1529129 | X32: =(J32/I32-1)*100 -> 7.5219876 | Y32: =(K32/J32-1)*100 -> 8.8711019 | ... AB32: =(N32/M32-1)*100 -> 12.083811 | AC32: 0.03 | AD32: Asia-Pacific | AE32: 0.208 | AF32: 0.20818182 | AG32: 0.20836364 | AH32: 0.20854545 | AI32: 0.20872727 | AJ32: 0.20890909 | AK32: 0.20909091 | AL32: 0.20927273 | AM32: 0.20945455 | AN32: 0.20963636 | AO32: 0.20981818 | AP32: 0.21
B33: Latin America | C33: =C29*AE33 -> 3575 | D33: =D29*AF33 -> 3659.3864 | E33: =E29*AG33 -> 3770.1364 | F33: =F29*AH33 -> 3907.3864 | G33: =G29*AI33 -> 4097.4545 | H33: =H29*AJ33 -> 4327.5 | I33: =I29*AK33 -> 4597.7273 | J33: =J29*AL33 -> 4947.8182 | ... N33: =N29*AP33 -> 7401.3175 | O33: =((N33/H33)^(1/7)-1)*100% -> 0.079682331 | Q33: Latin America | R33: =(D33/C33-1)*100 -> 2.3604577 | S33: =(E33/D33-1)*100 -> 3.0264637 | T33: =(F33/E33-1)*100 -> 3.6404519 | U33: =(G33/F33-1)*100 -> 4.8643304 | V33: =(H33/G33-1)*100 -> 5.6143504 | W33: =(I33/H33-1)*100 -> 6.2444199 | X33: =(J33/I33-1)*100 -> 7.614434 | Y33: =(K33/J33-1)*100 -> 8.9644655 | ... AB33: =(N33/M33-1)*100 -> 12.179185 | AC33: 0.04 | AD33: Latin America | AE33: 0.13 | AF33: 0.13022727 | AG33: 0.13045455 | AH33: 0.13068182 | AI33: 0.13090909 | AJ33: 0.13113636 | AK33: 0.13136364 | AL33: 0.13159091 | AM33: 0.13181818 | AN33: 0.13204545 | AO33: 0.13227273 | AP33: 0.1325
B34: Middle East & Africa | C34: =C29*AE34 -> 3190 | D34: =D29*AF34 -> 3271.0955 | E34: =E29*AG34 -> 3376.0455 | F34: =F29*AH34 -> 3505.0955 | G34: =G29*AI34 -> 3682.0182 | H34: =H29*AJ34 -> 3895.5 | I34: =I29*AK34 -> 4145.9091 | J34: =J29*AL34 -> 4469.2727 | ... N34: =N29*AP34 -> 6731.0095 | O34: =((N34/H34)^(1/7)-1)*100% -> 0.081262147 | Q34: Middle East & Africa | R34: =(D34/C34-1)*100 -> 2.5421773 | S34: =(E34/D34-1)*100 -> 3.2084053 | T34: =(F34/E34-1)*100 -> 3.8225196 | U34: =(G34/F34-1)*100 -> 5.0475866 | V34: =(H34/G34-1)*100 -> 5.7979567 | W34: =(I34/H34-1)*100 -> 6.428163 | X34: =(J34/I34-1)*100 -> 7.7995834 | Y34: =(K34/J34-1)*100 -> 9.1509703 | ... AB34: =(N34/M34-1)*100 -> 12.368252 | AC34: 0.05 | AD34: Middle East & Africa | AE34: 0.116 | AF34: 0.11640909 | AG34: 0.11681818 | AH34: 0.11722727 | AI34: 0.11763636 | AJ34: 0.11804545 | AK34: 0.11845455 | AL34: 0.11886364 | AM34: 0.11927273 | AN34: 0.11968182 | AO34: 0.12009091 | AP34: 0.1205
C37: 15125 | D37: 15449.891 | E37: 15884.491 | F37: 16428.691 | G37: 17192.236 | H37: 18120 | I37: 19211.818 | J37: 20632.145 | K37: 22435.509 | L37: 24648.945 | M37: 27343.309 | N37: 30610.732
C38: 5500 | D38: 5609.2709 | E38: 5757.9309 | F38: 5945.7509 | G38: 6212.1964 | H38: 6537 | I38: 6919.8182 | J38: 7419.5055 | K38: 8055.0691 | L38: 8835.5355 | M38: 9785.5491 | N38: 10937.192
C39: 3025 | D39: 3092.7882 | E39: 3182.6782 | F39: 3294.7082 | G39: 3450.9673 | H39: 3640.5 | I39: 3863.3636 | J39: 4152.7491 | K39: 4519.8218 | L39: 4970.2441 | M39: 5518.5418 | N39: 6183.5913
C40: 3850 | D40: 3935.2773 | E40: 4048.6273 | F40: 4190.0773 | G40: 4387.6909 | H40: 4627.5 | I40: 4909.5455 | J40: 5275.9636 | K40: 5740.8727 | L40: 6311.3886 | M40: 7005.8727 | N40: 7848.1895
C41: 2750 | D41: 2812.5545 | E41: 2895.2545 | F41: 2998.1545 | G41: 3141.3818 | H41: 3315 | I41: 3519.0909 | J41: 3783.9273 | K41: 4119.7455 | L41: 4531.7773 | M41: 5033.3455 | N41: 5641.759
C42: 12375 | D42: 12650.109 | E42: › | F42: 13471.309 | G42: 14107.764 | H42: 14880 | I42: 15788.182 | J42: 16967.855 | K42: 18464.491 | L42: 20301.055 | M42: 22536.691 | N42: 25248.268 | AH42: 2023 | AI42: 2030
C43: 3025 | D43: 3093.0436 | E43: 3183.2036 | F43: 3295.5236 | G43: 3452.1055 | H43: 3642 | I43: 3865.2727 | J43: 4155.1418 | K43: 4522.7964 | L43: 4973.9218 | M43: 5523.0764 | N43: 6189.1772 | AG43: =AD8 -> Flexible Electronics | AH43: =AI8 -> 0.54927273 | AI43: =AP8 -> 0.548
C44: 2475 | D44: 2532.8318 | E44: 2608.8818 | F44: 2703.2318 | G44: 2834.0727 | H44: 2992.5 | I44: 3178.6364 | J44: 3419.8909 | K44: 3725.6182 | L44: 4100.6659 | M44: 4557.2182 | N44: 5111.0985 | AG44: =AD13 -> Flexible Circuit | AH44: =AI13 -> 0.45072727 | AI44: =AP13 -> 0.452
C45: 3575 | D45: 3648.4018 | E45: 3747.5418 | F45: 3872.3218 | G45: 4048.5127 | H45: 4263 | I45: 4515.6364 | J45: 4844.9309 | K45: 5263.4582 | L45: 5777.3009 | M45: 6402.7782 | N45: 7161.1238
C46: 1925 | D46: 1968.2773 | E46: 2025.6273 | F46: 2097.0773 | G46: 2196.6909 | H46: 2317.5 | I46: 2459.5455 | J46: 2643.9636 | K46: 2877.8727 | L46: 3164.8886 | M46: 3514.2727 | N46: 3938.0595
C47: 1375 | D47: 1407.5545 | E47: 1450.2545 | F47: 1503.1545 | G47: 1576.3818 | H47: 1665 | I47: 1769.0909 | J47: 1903.9273 | K47: 2074.7455 | L47: 2284.2773 | M47: 2539.3455 | N47: 2848.809
AH55: 2023 | AI55: 2030
...

Sheet North America
B4: North America Flexible Electronics and Circuit Market | D4: Market Value (US$ Million) | Q4: North America Flexible Electronics and Circuit Market | S4: Market Y-o-Y Growth (%) | AD4: North America Flexible Electronics and Circuit Market | AF4: Market Share (%)
C5: 2019 | D5: 2020 | E5: 2021 | F5: 2022 | G5: 2023 | H5: 2024 | I5: 2025 | J5: 2026 | K5: 2027 | L5: 2028 | M5: 2029 | N5: 2030 | O5: CAGR (2023-2030) % | R5: 2020 | S5: 2021 | T5: 2022 | U5: 2023 | V5: 2024 | W5: 2025 | X5: 2026 | Y5: 2027 | Z5: 2028 | AA5: 2029 | AB5: 2030 | AE5: 2019 | AF5: 2020 | AG5: 2021 | AH5: 2022 | AI5: 2023 | AJ5: 2024 | AK5: 2025 | AL5: 2026 | AM5: 2027 | AN5: 2028 | AO5: 2029 | AP5: 2030
B7: By Type | C7: =Global!C30 -> 8525 | D7: =Global!D30 -> 8696.95 | E7: =Global!E30 -> 8930.1 | F7: =Global!F30 -> 9224.15 | G7: =Global!G30 -> 9640.4 | H7: =Global!H30 -> 10147.5 | I7: =Global!I30 -> 10745 | J7: =Global!J30 -> 11524.4 | ... N7: =Global!N30 -> 17009.066 | O7: =((N7/H7)^(1/7)-1)*100% -> 0.076579023 | Q7: By Type | R7: =(D7/C7-1)*100 -> 2.0170088 | S7: =(E7/D7-1)*100 -> 2.6808249 | T7: =(F7/E7-1)*100 -> 3.2927963 | U7: =(G7/F7-1)*100 -> 4.5126109 | V7: =(H7/G7-1)*100 -> 5.2601552 | W7: =(I7/H7-1)*100 -> 5.8881498 | X7: =(J7/I7-1)*100 -> 7.2536063 | Y7: =(K7/J7-1)*100 -> 8.5991462 | ... AB7: =(N7/M7-1)*100 -> 11.803183 | AD7: By Type | AE7: 1 | AF7: 1 | AG7: 1 | AH7: 1 | AI7: 1 | AJ7: 1 | AK7: 1 | AL7: 1 | AM7: 1 | AN7: 1 | AO7: 1 | AP7: 1
B8: Flexible Electronics | C8: =C7*AE8 -> 4518.25 | D8: =D7*AF8 -> 4607.4069 | E8: =E7*AG8 -> 4728.8939 | F8: =F7*AH8 -> 4882.5103 | G8: =G7*AI8 -> 5100.648 | H8: =H7*AJ8 -> 5366.6438 | I8: =I7*AK8 -> 5680.1977 | J8: =J7*AL8 -> 6089.5977 | ... N8: =N7*AP8 -> 8972.2821 | O8: =((N8/H8)^(1/7)-1)*100% -> 0.07618203 | Q8: Flexible Electronics | R8: =(D8/C8-1)*100 -> 1.9732622 | S8: =(E8/D8-1)*100 -> 2.6367748 | T8: =(F8/E8-1)*100 -> 3.2484646 | U8: =(G8/F8-1)*100 -> 4.4677365 | V8: =(H8/G8-1)*100 -> 5.2149403 | W8: =(I8/H8-1)*100 -> 5.8426456 | X8: =(J8/I8-1)*100 -> 7.2074956 | Y8: =(K8/J8-1)*100 -> 8.5524368 | ... AB8: =(N8/M8-1)*100 -> 11.755034 | AC8: 0.01 | AD8: Flexible Electronics | AE8: 0.53 | AF8: 0.52977273 | AG8: 0.52954545 | AH8: 0.52931818 | AI8: 0.52909091 | AJ8: 0.52886364 | AK8: 0.52863636 | AL8: 0.52840909 | AM8: 0.52818182 | AN8: 0.52795455 | AO8: 0.52772727 | AP8: 0.5275
B9: Flexible Displays | C9: =C7*AE9 -> 1662.375 | D9: =D7*AF9 -> 1690.8452 | E9: =E7*AG9 -> 1730.9781 | F9: =F7*AH9 -> 1782.6089 | G9: =G7*AI9 -> 1857.4422 | H9: =H7*AJ9 -> 1949.2425 | I9: =I7*AK9 -> 2057.7652 | J9: =J7*AL9 -> 2200.3223 | ... N9: =N7*AP9 -> 3207.9098 | O9: =((N9/H9)^(1/7)-1)*100% -> 0.07376202 | Q9: Flexible Displays | R9: =(D9/C9-1)*100 -> 1.7126224 | S9: =(E9/D9-1)*100 -> 2.373541 | T9: =(F9/E9-1)*100 -> 2.9827532 | U9: =(G9/F9-1)*100 -> 4.197962 | V9: =(H9/G9-1)*100 -> 4.9422987 | W9: =(I9/H9-1)*100 -> 5.5674285 | X9: =(J9/I9-1)*100 -> 6.9277623 | Y9: =(K9/J9-1)*100 -> 8.2682089 | ... AB9: =(N9/M9-1)*100 -> 11.459339 | AC9: 0.01 | AD9: Flexible Displays | AE9: 0.195 | AF9: 0.19441818 | AG9: 0.19383636 | AH9: 0.19325455 | AI9: 0.19267273 | AJ9: 0.19209091 | AK9: 0.19150909 | AL9: 0.19092727 | AM9: 0.19034545 | AN9: 0.18976364 | AO9: 0.18918182 | AP9: 0.1886
B10: Flexible Batteries | C10: =C7*AE10 -> 929.225 | D10: =D7*AF10 -> 949.54881 | E10: =E7*AG10 -> 976.62821 | F10: =F7*AH10 -> 1010.4637 | G10: =G7*AI10 -> 1057.8148 | H10: =H7*AJ10 -> 1115.3025 | I10: =I7*AK10 -> 1182.9268 | J10: =J7*AL10 -> 1270.827 | ... N10: =N7*AP10 -> 1888.0063 | O10: =((N10/H10)^(1/7)-1)*100% -> 0.07809909 | Q10: Flexible Batteries | R10: =(D10/C10-1)*100 -> 2.187179 | S10: =(E10/D10-1)*100 -> 2.8518171 | T10: =(F10/E10-1)*100 -> 3.4645216 | U10: =(G10/F10-1)*100 -> 4.6860758 | V10: =(H10/G10-1)*100 -> 5.4345713 | W10: =(I10/H10-1)*100 -> 6.0633163 | X10: =(J10/I10-1)*100 -> 7.4307386 | Y10: =(K10/J10-1)*100 -> 8.7782049 | ... AB10: =(N10/M10-1)*100 -> 11.986618 | AC10: 0.03 | AD10: Flexible Batteries | AE10: 0.109 | AF10: 0.10918182 | AG10: 0.10936364 | AH10: 0.10954545 | AI10: 0.10972727 | AJ10: 0.10990909 | AK10: 0.11009091 | AL10: 0.11027273 | AM10: 0.11045455 | AN10: 0.11063636 | AO10: 0.11081818 | AP10: 0.111
B11: Flexible Sensors | C11: =C7*AE11 -> 1150.875 | D11: =D7*AF11 -> 1175.2742 | E11: =E7*AG11 -> 1207.999 | F11: =F7*AH11 -> 1249.0338 | G11: =G7*AI11 -> 1306.7124 | H11: =H7*AJ11 -> 1376.8313 | I11: =I7*AK11 -> 1459.3664 | J11: =J7*AL11 -> 1566.7946 | ... N11: =N7*AP11 -> 2321.7374 | O11: =((N11/H11)^(1/7)-1)*100% -> 0.077504054 | Q11: Flexible Sensors | R11: =(D11/C11-1)*100 -> 2.1200563 | S11: =(E11/D11-1)*100 -> 2.7844382 | T11: =(F11/E11-1)*100 -> 3.3969221 | U11: =(G11/F11-1)*100 -> 4.6178603 | V11: =(H11/G11-1)*100 -> 5.3660507 | W11: =(I11/H11-1)*100 -> 5.99457 | X11: =(J11/I11-1)*100 -> 7.3612907 | Y11: =(K11/J11-1)*100 -> 8.7080721 | ... AB11: =(N11/M11-1)*100 -> 11.914987 | AC11: 0.02 | AD11: Flexible Sensors | AE11: 0.135 | AF11: 0.13513636 | AG11: 0.13527273 | AH11: 0.13540909 | AI11: 0.13554545 | AJ11: 0.13568182 | AK11: 0.13581818 | AL11: 0.13595455 | AM11: 0.13609091 | AN11: 0.13622727 | AO11: 0.13636364 | AP11: 0.1365
B12: Flexible Memory | C12: =C7*AE12 -> 775.775 | D12: =D7*AF12 -> 791.7387 | E12: =E7*AG12 -> 813.28856 | F12: =F7*AH12 -> 840.40392 | G12: =G7*AI12 -> 878.67864 | H12: =H7*AJ12 -> 925.2675 | I12: =I7*AK12 -> 980.13936 | J12: =J7*AL12 -> 1051.6539 | ... N12: =N7*AP12 -> 1554.6286 | O12: =((N12/H12)^(1/7)-1)*100% -> 0.076946655 | Q12: Flexible Memory | R12: =(D12/C12-1)*100 -> 2.0577748 | S12: =(E12/D12-1)*100 -> 2.7218398 | T12: =(F12/E12-1)*100 -> 3.3340392 | U12: =(G12/F12-1)*100 -> 4.5543242 | V12: =(H12/G12-1)*100 -> 5.3021501 | W12: =(I12/H12-1)*100 -> 5.9303784 | X12: =(J12/I12-1)*100 -> 7.2963624 | Y12: =(K12/J12-1)*100 -> 8.6424214 | ... AB12: =(N12/M12-1)*100 -> 11.847682 | AC12: 0.04 | AD12: Flexible Memory | AE12: 0.091 | AF12: 0.091036364 | AG12: 0.091072727 | AH12: 0.091109091 | AI12: 0.091145455 | AJ12: 0.091181818 | AK12: 0.091218182 | AL12: 0.091254545 | AM12: 0.091290909 | AN12: 0.091327273 | AO12: 0.091363636 | AP12: 0.0914
B13: Flexible Circuit | C13: =C7*AE13 -> 4006.75 | D13: =D7*AF13 -> 4089.5431 | E13: =E7*AG13 -> 4201.2061 | F13: =F7*AH13 -> 4341.6397 | G13: =G7*AI13 -> 4539.752 | H13: =H7*AJ13 -> 4780.8562 | I13: =I7*AK13 -> 5064.8023 | J13: =J7*AL13 -> 5434.8023 | ... N13: =N7*AP13 -> 8036.7834 | O13: =((N13/H13)^(1/7)-1)*100% -> 0.077023615 | Q13: Flexible Circuit | R13: =(D13/C13-1)*100 -> 2.06634 | S13: =(E13/D13-1)*100 -> 2.7304531 | T13: =(F13/E13-1)*100 -> 3.3426962 | U13: =(G13/F13-1)*100 -> 4.5630757 | V13: =(H13/G13-1)*100 -> 5.3109564 | W13: =(I13/H13-1)*100 -> 5.9392295 | X13: =(J13/I13-1)*100 -> 7.3053197 | Y13: =(K13/J13-1)*100 -> 8.6514831 | ... AB13: =(N13/M13-1)*100 -> 11.856987 | AC13: 0.02 | AD13: Flexible Circuit | AE13: 0.47 | AF13: 0.47022727 | AG13: 0.47045455 | AH13: 0.47068182 | AI13: 0.47090909 | AJ13: 0.47113636 | AK13: 0.47136364 | AL13: 0.47159091 | AM13: 0.47181818 | AN13: 0.47204545 | AO13: 0.47227273 | AP13: 0.4725
B14: Single Sided Flex Circuit | C14: =C7*AE14 -> 959.0625 | D14: =D7*AF14 -> 979.11844 | E14: =E7*AG14 -> 1006.0975 | F14: =F7*AH14 -> 1039.981 | G14: =G7*AI14 -> 1087.7 | H14: =H7*AJ14 -> 1145.745 | I14: =I7*AK14 -> 1214.0873 | J14: =J7*AL14 -> 1303.0953 | ... N14: =N7*AP14 -> 1928.828 | O14: =((N14/H14)^(1/7)-1)*100% -> 0.077246463 | Q14: Single Sided Flex Circuit | R14: =(D14/C14-1)*100 -> 2.091203 | S14: =(E14/D14-1)*100 -> 2.7554476 | T14: =(F14/E14-1)*100 -> 3.3678092 | U14: =(G14/F14-1)*100 -> 4.5884546 | V14: =(H14/G14-1)*100 -> 5.336486 | W14: =(I14/H14-1)*100 -> 5.9648803 | X14: =(J14/I14-1)*100 -> 7.3312701 | Y14: =(K14/J14-1)*100 -> 8.6777273 | ... AB14: =(N14/M14-1)*100 -> 11.883908 | AC14: 0.02 | AD14: Single Sided Flex Circuit | AE14: 0.1125 | AF14: 0.11258182 | AG14: 0.11266364 | AH14: 0.11274545 | AI14: 0.11282727 | AJ14: 0.11290909 | AK14: 0.11299091 | AL14: 0.11307273 | AM14: 0.11315455 | AN14: 0.11323636 | AO14: 0.11331818 | AP14: 0.1134
B15: Double Sided Flex Circuit | C15: =C7*AE15 -> 852.5 | D15: =D7*AF15 -> 870.24844 | E15: =E7*AG15 -> 894.14656 | F15: =F7*AH15 -> 924.17597 | G15: =G7*AI15 -> 966.49392 | H15: =H7*AJ15 -> 1017.9788 | I15: =I7*AK15 -> 1078.6026 | J15: =J7*AL15 -> 1157.5736 | ... N15: =N7*AP15 -> 1712.8129 | O15: =((N15/H15)^(1/7)-1)*100% -> 0.077163433 | Q15: Double Sided Flex Circuit | R15: =(D15/C15-1)*100 -> 2.0819287 | S15: =(E15/D15-1)*100 -> 2.7461257 | T15: =(F15/E15-1)*100 -> 3.3584445 | U15: =(G15/F15-1)*100 -> 4.5789922 | V15: =(H15/G15-1)*100 -> 5.3269688 | W15: =(I15/H15-1)*100 -> 5.9553194 | X15: =(J15/I15-1)*100 -> 7.321599 | Y15: =(K15/J15-1)*100 -> 8.6679482 | ... AB15: =(N15/M15-1)*100 -> 11.873881 | AC15: 0.03 | AD15: Double Sided Flex Circuit | AE15: 0.1 | AF15: 0.10006364 | AG15: 0.10012727 | AH15: 0.10019091 | AI15: 0.10025455 | AJ15: 0.10031818 | AK15: 0.10038182 | AL15: 0.10044545 | AM15: 0.10050909 | AN15: 0.10057273 | AO15: 0.10063636 | AP15: 0.1007
B16: Multilayer Flex Circuit | C16: =C7*AE16 -> 1121.0375 | D16: =D7*AF16 -> 1142.463 | E16: =E7*AG16 -> 1171.8727 | F16: =F7*AH16 -> 1209.2022 | G16: =G7*AI16 -> 1262.4542 | H16: =H7*AJ16 -> 1327.4775 | I16: =I7*AK16 -> 1404.1761 | J16: =J7*AL16 -> 1504.458 | ... N16: =N7*AP16 -> 2211.1785 | O16: =((N16/H16)^(1/7)-1)*100% -> 0.075614535 | Q16: Multilayer Flex Circuit | R16: =(D16/C16-1)*100 -> 1.9112186 | S16: =(E16/D16-1)*100 -> 2.5742358 | T16: =(F16/E16-1)*100 -> 3.1854605 | U16: =(G16/F16-1)*100 -> 4.4038946 | V16: =(H16/G16-1)*100 -> 5.1505472 | W16: =(I16/H16-1)*100 -> 5.777773 | X16: =(J16/I16-1)*100 -> 7.1416895 | Y16: =(K16/J16-1)*100 -> 8.4857069 | ... AB16: =(N16/M16-1)*100 -> 11.68603 | AC16: 0.01 | AD16: Multilayer Flex Circuit | AE16: 0.1315 | AF16: 0.13136364 | AG16: 0.13122727 | AH16: 0.13109091 | AI16: 0.13095455 | AJ16: 0.13081818 | AK16: 0.13068182 | AL16: 0.13054545 | AM16: 0.13040909 | AN16: 0.13027273 | AO16: 0.13013636 | AP16: 0.13
B17: Rigid Flex Circuit | C17: =C7*AE17 -> 639.375 | D17: =D7*AF17 -> 653.53626 | E17: =E7*AG17 -> 672.35535 | F17: =F7*AH17 -> 695.83633 | G17: =G7*AI17 -> 728.63896 | H17: =H7*AJ17 -> 768.4425 | I17: =I7*AK17 -> 815.25245 | J17: =J7*AL17 -> 876.06393 | ... N17: =N7*AP17 -> 1302.8944 | O17: =((N17/H17)^(1/7)-1)*100% -> 0.078342781 | Q17: Rigid Flex Circuit | R17: =(D17/C17-1)*100 -> 2.21486 | S17: =(E17/D17-1)*100 -> 2.879578 | T17: =(F17/E17-1)*100 -> 3.4923477 | U17: =(G17/F17-1)*100 -> 4.7141296 | V17: =(H17/G17-1)*100 -> 5.4627246 | W17: =(I17/H17-1)*100 -> 6.0915364 | X17: =(J17/I17-1)*100 -> 7.4592207 | Y17: =(K17/J17-1)*100 -> 8.8069417 | ... AB17: =(N17/M17-1)*100 -> 12.015889 | AC17: 0.04 | AD17: Rigid Flex Circuit | AE17: 0.075 | AF17: 0.075145455 | AG17: 0.075290909 | AH17: 0.075436364 | AI17: 0.075581818 | AJ17: 0.075727273 | AK17: 0.075872727 | AL17: 0.076018182 | AM17: 0.076163636 | AN17: 0.076309091 | AO17: 0.076454545 | AP17: 0.0766
B18: Others | C18: =C7*AE18 -> 434.775 | D18: =D7*AF18 -> 444.17696 | E18: =E7*AG18 -> 456.73402 | F18: =F7*AH18 -> 472.44419 | G18: =G7*AI18 -> 494.46488 | H18: =H7*AJ18 -> 521.2125 | I18: =I7*AK18 -> 552.68373 | J18: =J7*AL18 -> 593.61137 | ... N18: =N7*AP18 -> 881.06959 | O18: =((N18/H18)^(1/7)-1)*100% -> 0.077880885 | Q18: Others | R18: =(D18/C18-1)*100 -> 2.1624876 | S18: =(E18/D18-1)*100 -> 2.8270418 | T18: =(F18/E18-1)*100 -> 3.4396755 | U18: =(G18/F18-1)*100 -> 4.6610136 | V18: =(H18/G18-1)*100 -> 5.4094074 | W18: =(I18/H18-1)*100 -> 6.0380799 | X18: =(J18/I18-1)*100 -> 7.4052551 | Y18: =(K18/J18-1)*100 -> 8.7524806 | ... AB18: =(N18/M18-1)*100 -> 11.960376 | AC18: 0.05 | AD18: Others | AE18: 0.051 | AF18: 0.051072727 | AG18: 0.051145455 | AH18: 0.051218182 | AI18: 0.051290909 | AJ18: 0.051363636 | AK18: 0.051436364 | AL18: 0.051509091 | AM18: 0.051581818 | AN18: 0.051654545 | AO18: 0.051727273 | AP18: 0.0518
B20: By Vertical | C20: =C7 -> 8525 | D20: =D7 -> 8696.95 | E20: =E7 -> 8930.1 | F20: =F7 -> 9224.15 | G20: =G7 -> 9640.4 | H20: =H7 -> 10147.5 | I20: =I7 -> 10745 | J20: =J7 -> 11524.4 | ... N20: =N7 -> 17009.066 | O20: =((N20/H20)^(1/7)-1)*100% -> 0.076579023 | Q20: By Vertical | R20: =(D20/C20-1)*100 -> 2.0170088 | S20: =(E20/D20-1)*100 -> 2.6808249 | T20: =(F20/E20-1)*100 -> 3.2927963 | U20: =(G20/F20-1)*100 -> 4.5126109 | V20: =(H20/G20-1)*100 -> 5.2601552 | W20: =(I20/H20-1)*100 -> 5.8881498 | X20: =(J20/I20-1)*100 -> 7.2536063 | Y20: =(K20/J20-1)*100 -> 8.5991462 | ... AB20: =(N20/M20-1)*100 -> 11.803183 | AD20: By Vertical | AE20: 1 | AF20: 1 | AG20: 1 | AH20: 1 | AI20: 1 | AJ20: 1 | AK20: 1 | AL20: 1 | AM20: 1 | AN20: 1 | AO20: 1 | AP20: 1
B21: Automotive | C21: =C20*AE21 -> 1420.73 | D21: =D20*AF21 -> 1450.2128 | E21: =E20*AG21 -> 1489.9392 | F21: =F20*AH21 -> 1539.8766 | G21: =G20*AI21 -> 1610.2814 | H21: =H20*AJ21 -> 1695.9492 | I21: =I20*AK21 -> 1796.8304 | J21: =J20*AL21 -> 1928.2607 | ... N21: =N20*AP21 -> 2852.4203 | O21: =((N21/H21)^(1/7)-1)*100% -> 0.077103014 | Q21: Automotive | R21: =(D21/C21-1)*100 -> 2.075188 | S21: =(E21/D21-1)*100 -> 2.7393493 | T21: =(F21/E21-1)*100 -> 3.3516359 | U21: =(G21/F21-1)*100 -> 4.5721116 | V21: =(H21/G21-1)*100 -> 5.3200473 | W21: =(I21/H21-1)*100 -> 5.948365 | X21: =(J21/I21-1)*100 -> 7.3145633 | Y21: =(K21/J21-1)*100 -> 8.6608328 | ... AB21: =(N21/M21-1)*100 -> 11.866582 | AC21: 0.03 | AD21: Automotive | AE21: 0.16665455 | AF21: 0.16674959 | AG21: 0.16684463 | AH21: 0.16693967 | AI21: 0.16703471 | AJ21: 0.16712975 | AK21: 0.16722479 | AL21: 0.16731983 | AM21: 0.16741488 | AN21: 0.16750992 | AO21: 0.16760496 | AP21: 0.1677
B22: Military, Defense and Aerospace | C22: =C20*AE22 -> 1073.84 | D22: =D20*AF22 -> 1096.2398 | E22: =E20*AG22 -> 1126.3882 | F22: =F20*AH22 -> 1164.2631 | G22: =G20*AI22 -> 1217.6224 | H22: =H20*AJ22 -> 1282.535 | I22: =I20*AK22 -> 1358.9672 | J22: =J20*AL22 -> 1458.5223 | ... N22: =N20*AP22 -> 2158.4504 | O22: =((N22/H22)^(1/7)-1)*100% -> 0.077199449 | Q22: Military, Defense and Aerospace | R22: =(D22/C22-1)*100 -> 2.0859501 | S22: =(E22/D22-1)*100 -> 2.7501679 | T22: =(F22/E22-1)*100 -> 3.3625055 | U22: =(G22/F22-1)*100 -> 4.5830958 | V22: =(H22/G22-1)*100 -> 5.3310963 | W22: =(I22/H22-1)*100 -> 5.9594661 | X22: =(J22/I22-1)*100 -> 7.3257937 | Y22: =(K22/J22-1)*100 -> 8.67219 | ... AB22: =(N22/M22-1)*100 -> 11.878231 | AC22: 0.04 | AD22: Military, Defense and Aerospace | AE22: 0.12596364 | AF22: 0.12604876 | AG22: 0.12613388 | AH22: 0.12621901 | AI22: 0.12630413 | AJ22: 0.12638926 | AK22: 0.12647438 | AL22: 0.1265595 | AM22: 0.12664463 | AN22: 0.12672975 | AO22: 0.12681488 | AP22: 0.1269
B23: Consumer Electronics | C23: =C20*AE23 -> 2088.625 | D23: =D20*AF23 -> 2128.2227 | E23: =E20*AG23 -> 2182.6788 | F23: =F20*AH23 -> 2251.8666 | G23: =G20*AI23 -> 2350.6801 | H23: =H20*AJ23 -> 2471.3775 | I23: =I20*AK23 -> 2613.7701 | J23: =J20*AL23 -> 2800.0101 | ... N23: =N20*AP23 -> 4112.792 | O23: =((N23/H23)^(1/7)-1)*100% -> 0.075473382 | Q23: Consumer Electronics | R23: =(D23/C23-1)*100 -> 1.8958754 | S23: =(E23/D23-1)*100 -> 2.5587584 | T23: =(F23/E23-1)*100 -> 3.1698561 | U23: =(G23/F23-1)*100 -> 4.3880707 | V23: =(H23/G23-1)*100 -> 5.1345745 | W23: =(I23/H23-1)*100 -> 5.761669 | X23: =(J23/I23-1)*100 -> 7.1253413 | Y23: =(K23/J23-1)*100 -> 8.4691165 | ... AB23: =(N23/M23-1)*100 -> 11.668835 | AC23: 0.01 | AD23: Consumer Electronics | AE23: 0.245 | AF23: 0.24470909 | AG23: 0.24441818 | AH23: 0.24412727 | AI23: 0.24383636 | AJ23: 0.24354545 | AK23: 0.24325455 | AL23: 0.24296364 | AM23: 0.24267273 | AN23: 0.24238182 | AO23: 0.24209091 | AP23: 0.2418
B24: Industrial | C24: =C20*AE24 -> 984.715 | D24: =D20*AF24 -> 1004.9649 | E24: =E20*AG24 -> 1032.3048 | F24: =F20*AH24 -> 1066.7081 | G24: =G20*AI24 -> 1115.2748 | H24: =H20*AJ24 -> 1174.3928 | I24: =I20*AK24 -> 1244.0224 | J24: =J20*AL24 -> 1334.7732 | ... N24: =N20*AP24 -> 1973.0516 | O24: =((N24/H24)^(1/7)-1)*100% -> 0.076934509 | Q24: Industrial | R24: =(D24/C24-1)*100 -> 2.0564241 | S24: =(E24/D24-1)*100 -> 2.7204813 | T24: =(F24/E24-1)*100 -> 3.3326737 | U24: =(G24/F24-1)*100 -> 4.5529437 | V24: =(H24/G24-1)*100 -> 5.3007607 | W24: =(I24/H24-1)*100 -> 5.9289819 | X24: =(J24/I24-1)*100 -> 7.294949 | Y24: =(K24/J24-1)*100 -> 8.6409914 | ... AB24: =(N24/M24-1)*100 -> 11.846213 | AC24: 0.05 | AD24: Industrial | AE24: 0.11550909 | AF24: 0.11555372 | AG24: 0.11559835 | AH24: 0.11564298 | AI24: 0.1156876 | AJ24: 0.11573223 | AK24: 0.11577686 | AL24: 0.11582149 | AM24: 0.11586612 | AN24: 0.11591074 | AO24: 0.11595537 | AP24: 0.116
B25: Healthcare and Medical | C25: =C20*AE25 -> 1547.21 | D25: =D20*AF25 -> 1577.2386 | E25: =E20*AG25 -> 1618.3112 | F25: =F20*AH25 -> 1670.3487 | G25: =G20*AI25 -> 1744.4184 | H25: =H20*AJ25 -> 1834.8022 | I25: =I20*AK25 -> 1941.3817 | J25: =J20*AL25 -> 2080.6399 | ... N25: =N20*AP25 -> 3061.6318 | O25: =((N25/H25)^(1/7)-1)*100% -> 0.075885971 | Q25: Healthcare and Medical | R25: =(D25/C25-1)*100 -> 1.9408226 | S25: =(E25/D25-1)*100 -> 2.6040857 | T25: =(F25/E25-1)*100 -> 3.215542 | U25: =(G25/F25-1)*100 -> 4.4343858 | V25: =(H25/G25-1)*100 -> 5.1813115 | W25: =(I25/H25-1)*100 -> 5.8087763 | X25: =(J25/I25-1)*100 -> 7.173149 | Y25: =(K25/J25-1)*100 -> 8.5176183 | ... AB25: =(N25/M25-1)*100 -> 11.719061 | AC25: 0.02 | AD25: Healthcare and Medical | AE25: 0.18149091 | AF25: 0.18135537 | AG25: 0.18121983 | AH25: 0.1810843 | AI25: 0.18094876 | AJ25: 0.18081322 | AK25: 0.18067769 | AL25: 0.18054215 | AM25: 0.18040661 | AN25: 0.18027107 | AO25: 0.18013554 | AP25: 0.18
B26: Energy and Power | C26: =C20*AE26 -> 842.0375 | D26: =D20*AF26 -> 859.67554 | E26: =E20*AG26 -> 883.39354 | F26: =F20*AH26 -> 913.1756 | G26: =G20*AI26 -> 955.10869 | H26: =H20*AJ26 -> 1006.112 | I26: =I20*AK26 -> 1066.1615 | J26: =J20*AL26 -> 1144.3634 | ... N26: =N20*AP26 -> 1694.1029 | O26: =((N26/H26)^(1/7)-1)*100% -> 0.077277613 | Q26: Energy and Power | R26: =(D26/C26-1)*100 -> 2.0946856 | S26: =(E26/D26-1)*100 -> 2.7589477 | T26: =(F26/E26-1)*100 -> 3.3713249 | U26: =(G26/F26-1)*100 -> 4.5920066 | V26: =(H26/G26-1)*100 -> 5.340058 | W26: =(I26/H26-1)*100 -> 5.9684684 | X26: =(J26/I26-1)*100 -> 7.334899 | Y26: =(K26/J26-1)*100 -> 8.6813963 | ... AB26: =(N26/M26-1)*100 -> 11.887668 | AC26: 0.06 | AD26: Energy and Power | AE26: 0.098772727 | AF26: 0.098847934 | AG26: 0.09892314 | AH26: 0.098998347 | AI26: 0.099073554 | AJ26: 0.09914876 | AK26: 0.099223967 | AL26: 0.099299174 | AM26: 0.09937438 | AN26: 0.099449587 | AO26: 0.099524793 | AP26: 0.0996
B27: Others | C27: =C20*AE27 -> 567.8425 | D27: =D20*AF27 -> 580.39563 | E27: =E20*AG27 -> 597.0842 | F27: =F20*AH27 -> 617.91132 | G27: =G20*AI27 -> 647.01425 | H27: =H20*AJ27 -> 682.33132 | I27: =I20*AK27 -> 723.86667 | J27: =J20*AL27 -> 777.83033 | ... N27: =N20*AP27 -> 1156.6165 | O27: =((N27/H27)^(1/7)-1)*100% -> 0.078305968 | Q27: Others | R27: =(D27/C27-1)*100 -> 2.2106711 | S27: =(E27/D27-1)*100 -> 2.875378 | T27: =(F27/E27-1)*100 -> 3.4881388 | U27: =(G27/F27-1)*100 -> 4.7098872 | V27: =(H27/G27-1)*100 -> 5.4584682 | W27: =(I27/H27-1)*100 -> 6.0872708 | X27: =(J27/I27-1)*100 -> 7.4549165 | Y27: =(K27/J27-1)*100 -> 8.8026 | ... AB27: =(N27/M27-1)*100 -> 12.011469 | AC27: 0.07 | AD27: Others | AE27: 0.066609091 | AF27: 0.066735537 | AG27: 0.066861983 | AH27: 0.06698843 | AI27: 0.067114876 | AJ27: 0.067241322 | AK27: 0.067367769 | AL27: 0.067494215 | AM27: 0.067620661 | AN27: 0.067747107 | AO27: 0.067873554 | AP27: 0.068
B29: By Country | C29: =C20 -> 8525 | D29: =D20 -> 8696.95 | E29: =E20 -> 8930.1 | F29: =F20 -> 9224.15 | G29: =G20 -> 9640.4 | H29: =H20 -> 10147.5 | I29: =I20 -> 10745 | J29: =J20 -> 11524.4 | ... N29: =N20 -> 17009.066 | O29: =((N29/H29)^(1/7)-1)*100% -> 0.076579023 | Q29: By Country | R29: =(D29/C29-1)*100 -> 2.0170088 | S29: =(E29/D29-1)*100 -> 2.6808249 | T29: =(F29/E29-1)*100 -> 3.2927963 | U29: =(G29/F29-1)*100 -> 4.5126109 | V29: =(H29/G29-1)*100 -> 5.2601552 | W29: =(I29/H29-1)*100 -> 5.8881498 | X29: =(J29/I29-1)*100 -> 7.2536063 | Y29: =(K29/J29-1)*100 -> 8.5991462 | ... AB29: =(N29/M29-1)*100 -> 11.803183 | AD29: By Country | AE29: 1 | AF29: 1 | AG29: 1 | AH29: 1 | AI29: 1 | AJ29: 1 | AK29: 1 | AL29: 1 | AM29: 1 | AN29: 1 | AO29: 1 | AP29: 1
B30: The U.S. | C30: =C29*AE30 -> 3452.625 | D30: =D29*AF30 -> 3523.0554 | E30: =E29*AG30 -> 3618.3142 | F30: =F29*AH30 -> 3738.2964 | G30: =G29*AI30 -> 3907.8676 | H30: =H29*AJ30 -> 4114.35 | I30: =I29*AK30 -> 4357.5859 | J30: =J29*AL30 -> 4674.7157 | ... N30: =N29*AP30 -> 6905.6806 | O30: =((N30/H30)^(1/7)-1)*100% -> 0.076785806 | Q30: The U.S. | R30: =(D30/C30-1)*100 -> 2.0399082 | S30: =(E30/D30-1)*100 -> 2.7038682 | T30: =(F30/E30-1)*100 -> 3.3159717 | U30: =(G30/F30-1)*100 -> 4.5360548 | V30: =(H30/G30-1)*100 -> 5.2837614 | W30: =(I30/H30-1)*100 -> 5.9118915 | X30: =(J30/I30-1)*100 -> 7.2776488 | Y30: =(K30/J30-1)*100 -> 8.6234848 | ... AB30: =(N30/M30-1)*100 -> 11.828223 | AC30: 0.01 | AD30: The U.S. | AE30: 0.405 | AF30: 0.40509091 | AG30: 0.40518182 | AH30: 0.40527273 | AI30: 0.40536364 | AJ30: 0.40545455 | AK30: 0.40554545 | AL30: 0.40563636 | AM30: 0.40572727 | AN30: 0.40581818 | AO30: 0.40590909 | AP30: 0.406
B31: Canada | C31: =C29*AE31 -> 2821.775 | D31: =D29*AF31 -> 2874.7373 | E31: =E29*AG31 -> 2947.7448 | F31: =F29*AH31 -> 3040.6153 | G31: =G29*AI31 -> 3173.4444 | H31: =H29*AJ31 -> 3335.76 | I31: =I29*AK31 -> 3527.2905 | J31: =J29*AL31 -> 3777.9079 | ... N31: =N29*AP31 -> 5544.9554 | O31: =((N31/H31)^(1/7)-1)*100% -> 0.075298492 | Q31: Canada | R31: =(D31/C31-1)*100 -> 1.876914 | S31: =(E31/D31-1)*100 -> 2.5396246 | T31: =(F31/E31-1)*100 -> 3.1505589 | U31: =(G31/F31-1)*100 -> 4.3684953 | V31: =(H31/G31-1)*100 -> 5.1148084 | W31: =(I31/H31-1)*100 -> 5.7417337 | X31: =(J31/I31-1)*100 -> 7.1050968 | Y31: =(K31/J31-1)*100 -> 8.448565 | ... AB31: =(N31/M31-1)*100 -> 11.647512 | AC31: 0.02 | AD31: Canada | AE31: 0.331 | AF31: 0.33054545 | AG31: 0.33009091 | AH31: 0.32963636 | AI31: 0.32918182 | AJ31: 0.32872727 | AK31: 0.32827273 | AL31: 0.32781818 | AM31: 0.32736364 | AN31: 0.32690909 | AO31: 0.32645455 | AP31: 0.326
B32: Mexico | C32: =C29*AE32 -> 2250.6 | D32: =D29*AF32 -> 2299.1573 | E32: =E29*AG32 -> 2364.041 | F32: =F29*AH32 -> 2445.2383 | G32: =G29*AI32 -> 2559.088 | H32: =H29*AJ32 -> 2697.39 | I32: =I29*AK32 -> 2860.1236 | J32: =J29*AL32 -> 3071.7764 | ... N32: =N29*AP32 -> 4558.4296 | O32: =((N32/H32)^(1/7)-1)*100% -> 0.077836961 | Q32: Mexico | R32: =(D32/C32-1)*100 -> 2.1575281 | S32: =(E32/D32-1)*100 -> 2.822064 | T32: =(F32/E32-1)*100 -> 3.434682 | U32: =(G32/F32-1)*100 -> 4.6559753 | V32: =(H32/G32-1)*100 -> 5.4043472 | W32: =(I32/H32-1)*100 -> 6.0330036 | X32: =(J32/I32-1)*100 -> 7.4001276 | Y32: =(K32/J32-1)*100 -> 8.7473032 | ... AB32: =(N32/M32-1)*100 -> 11.95509 | AC32: 0.03 | AD32: Mexico | AE32: 0.264 | AF32: 0.26436364 | AG32: 0.26472727 | AH32: 0.26509091 | AI32: 0.26545455 | AJ32: 0.26581818 | AK32: 0.26618182 | AL32: 0.26654545 | AM32: 0.26690909 | AN32: 0.26727273 | AO32: 0.26763636 | AP32: 0.268
AM37: 2023 | AN37: 2030
AL38: =AD8 -> Flexible Electronics | AM38: =AI8 -> 0.52909091 | AN38: =AP8 -> 0.5275
AL39: =AD13 -> Flexible Circuit | AM39: =AI13 -> 0.47090909 | AN39: =AP13 -> 0.4725
AM53: 2023 | AN53: 2030
AL54: =AD21 -> Automotive | AM54: =AI21 -> 0.16703471 | AN54: =AP21 -> 0.1677
AL55: =AD22 -> Military, Defense and Aerospace | AM55: =AI22 -> 0.12630413 | AN55: =AP22 -> 0.1269
AL56: =AD23 -> Consumer Electronics | AM56: =AI23 -> 0.24383636 | AN56: =AP23 -> 0.2418
AL57: =AD24 -> Industrial | AM57: =AI24 -> 0.1156876 | AN57: =AP24 -> 0.116
AL58: =AD25 -> Healthcare and Medical | AM58: =AI25 -> 0.18094876 | AN58: =AP25 -> 0.18
AL59: =AD26 -> Energy and Power | AM59: =AI26 -> 0.099073554 | AN59: =AP26 -> 0.0996
AL60: =AD27 -> Others | AM60: =AI27 -> 0.067114876 | AN60: =AP27 -> 0.068
AM69: 2023 | AN69: 2030
AL70: =AD30 -> The U.S. | AM70: =AI30 -> 0.40536364 | AN70: =AP30 -> 0.406
AL71: =AD31 -> Canada | AM71: =AI31 -> 0.32918182 | AN71: =AP31 -> 0.326
...

Sheet Europe
B4: Europe Flexible Electronics and Circuit Market | D4: Market Value (US$ Million) | Q4: Europe Flexible Electronics and Circuit Market | S4: Market Y-o-Y Growth (%) | AD4: Europe Flexible Electronics and Circuit Market | AF4: Market Share (%)
C5: 2019 | D5: 2020 | E5: 2021 | F5: 2022 | G5: 2023 | H5: 2024 | I5: 2025 | J5: 2026 | K5: 2027 | L5: 2028 | M5: 2029 | N5: 2030 | O5: CAGR (2023-2030) % | R5: 2020 | S5: 2021 | T5: 2022 | U5: 2023 | V5: 2024 | W5: 2025 | X5: 2026 | Y5: 2027 | Z5: 2028 | AA5: 2029 | AB5: 2030 | AE5: 2019 | AF5: 2020 | AG5: 2021 | AH5: 2022 | AI5: 2023 | AJ5: 2024 | AK5: 2025 | AL5: 2026 | AM5: 2027 | AN5: 2028 | AO5: 2029 | AP5: 2030
B7: By Type | C7: =Global!C31 -> 6490 | D7: =Global!D31 -> 6622.6591 | E7: =Global!E31 -> 6802.0091 | F7: =Global!F31 -> 7027.8591 | G7: =Global!G31 -> 7346.9636 | H7: =Global!H31 -> 7735.5 | I7: =Global!I31 -> 8193.1818 | J7: =Global!J31 -> 8789.8545 | ... N7: =Global!N31 -> 12987.218 | O7: =((N7/H7)^(1/7)-1)*100% -> 0.076829185 | Q7: By Type | R7: =(D7/C7-1)*100 -> 2.0440538 | S7: =(E7/D7-1)*100 -> 2.7081267 | T7: =(F7/E7-1)*100 -> 3.3203425 | U7: =(G7/F7-1)*100 -> 4.5405655 | V7: =(H7/G7-1)*100 -> 5.2883937 | W7: =(I7/H7-1)*100 -> 5.9166417 | X7: =(J7/I7-1)*100 -> 7.282552 | Y7: =(K7/J7-1)*100 -> 8.6285428 | ... AB7: =(N7/M7-1)*100 -> 11.833721 | AD7: By Type | AE7: 1 | AF7: 1 | AG7: 1 | AH7: 1 | AI7: 1 | AJ7: 1 | AK7: 1 | AL7: 1 | AM7: 1 | AN7: 1 | AO7: 1 | AP7: 1
B8: Flexible Electronics | C8: =C7*AE8 -> 3472.15 | D8: =D7*AF8 -> 3541.0154 | E8: =E7*AG8 -> 3634.7463 | F8: =F7*AH8 -> 3753.1962 | G8: =G7*AI8 -> 3921.2749 | H8: =H7*AJ8 -> 4126.186 | I8: =I7*AK8 -> 4367.7107 | J8: =J7*AL8 -> 4682.9948 | ... N8: =N7*AP8 -> 6902.7061 | O8: =((N8/H8)^(1/7)-1)*100% -> 0.076277766 | Q8: Flexible Electronics | R8: =(D8/C8-1)*100 -> 1.9833649 | S8: =(E8/D8-1)*100 -> 2.6470065 | T8: =(F8/E8-1)*100 -> 3.2588214 | U8: =(G8/F8-1)*100 -> 4.4782807 | V8: =(H8/G8-1)*100 -> 5.225626 | W8: =(I8/H8-1)*100 -> 5.8534618 | X8: =(J8/I8-1)*100 -> 7.2185191 | Y8: =(K8/J8-1)*100 -> 8.5636678 | ... AB8: =(N8/M8-1)*100 -> 11.766812 | AC8: 0.01 | AD8: Flexible Electronics | AE8: 0.535 | AF8: 0.53468182 | AG8: 0.53436364 | AH8: 0.53404545 | AI8: 0.53372727 | AJ8: 0.53340909 | AK8: 0.53309091 | AL8: 0.53277273 | AM8: 0.53245455 | AN8: 0.53213636 | AO8: 0.53181818 | AP8: 0.5315
B9: Flexible Displays | C9: =C7*AE9 -> 1272.04 | D9: =D7*AF9 -> 1295.934 | E9: =E7*AG9 -> 1328.8652 | F9: =F7*AH9 -> 1370.752 | G9: =G7*AI9 -> 1430.6542 | H9: =H7*AJ9 -> 1503.8515 | I9: =I7*AK9 -> 1590.2221 | J9: =J7*AL9 -> 1703.2341 | ... N9: =N7*AP9 -> 2500.0394 | O9: =((N9/H9)^(1/7)-1)*100% -> 0.075312156 | Q9: Flexible Displays | R9: =(D9/C9-1)*100 -> 1.8783979 | S9: =(E9/D9-1)*100 -> 2.5411216 | T9: =(F9/E9-1)*100 -> 3.1520683 | U9: =(G9/F9-1)*100 -> 4.3700262 | V9: =(H9/G9-1)*100 -> 5.1163539 | W9: =(I9/H9-1)*100 -> 5.743292 | X9: =(J9/I9-1)*100 -> 7.106679 | Y9: =(K9/J9-1)*100 -> 8.4501708 | ... AB9: =(N9/M9-1)*100 -> 11.649177 | AC9: 0.01 | AD9: Flexible Displays | AE9: 0.196 | AF9: 0.19568182 | AG9: 0.19536364 | AH9: 0.19504545 | AI9: 0.19472727 | AJ9: 0.19440909 | AK9: 0.19409091 | AL9: 0.19377273 | AM9: 0.19345455 | AN9: 0.19313636 | AO9: 0.19281818 | AP9: 0.1925
B10: Flexible Batteries | C10: =C7*AE10 -> 720.39 | D10: =D7*AF10 -> 734.5131 | E10: =E7*AG10 -> 753.78628 | F10: =F7*AH10 -> 778.17567 | G10: =G7*AI10 -> 812.84134 | H10: =H7*AJ10 -> 855.12436 | I10: =I7*AK10 -> 904.97417 | J10: =J7*AL10 -> 970.08031 | ... N10: =N7*AP10 -> 1428.5939 | O10: =((N10/H10)^(1/7)-1)*100% -> 0.076068532 | Q10: Flexible Batteries | R10: =(D10/C10-1)*100 -> 1.9604796 | S10: =(E10/D10-1)*100 -> 2.6239397 | T10: =(F10/E10-1)*100 -> 3.2355842 | U10: =(G10/F10-1)*100 -> 4.4547358 | V10: =(H10/G10-1)*100 -> 5.201879 | W10: =(I10/H10-1)*100 -> 5.8295392 | X10: =(J10/I10-1)*100 -> 7.1942536 | Y10: =(K10/J10-1)*100 -> 8.539063 | ... AB10: =(N10/M10-1)*100 -> 11.741373 | AC10: 0.03 | AD10: Flexible Batteries | AE10: 0.111 | AF10: 0.11090909 | AG10: 0.11081818 | AH10: 0.11072727 | AI10: 0.11063636 | AJ10: 0.11054545 | AK10: 0.11045455 | AL10: 0.11036364 | AM10: 0.11027273 | AN10: 0.11018182 | AO10: 0.11009091 | AP10: 0.11
B11: Flexible Sensors | C11: =C7*AE11 -> 892.375 | D11: =D7*AF11 -> 910.91665 | E11: =E7*AG11 -> 935.89461 | F11: =F7*AH11 -> 967.28897 | G11: =G7*AI11 -> 1011.5433 | H11: =H7*AJ11 -> 1065.3893 | I11: =I7*AK11 -> 1128.797 | J11: =J7*AL11 -> 1211.4018 | ... N11: =N7*AP11 -> 1792.236 | O11: =((N11/H11)^(1/7)-1)*100% -> 0.077133546 | Q11: Flexible Sensors | R11: =(D11/C11-1)*100 -> 2.0777874 | S11: =(E11/D11-1)*100 -> 2.7420686 | T11: =(F11/E11-1)*100 -> 3.3544754 | U11: =(G11/F11-1)*100 -> 4.5750901 | V11: =(H11/G11-1)*100 -> 5.3231538 | W11: =(I11/H11-1)*100 -> 5.9515977 | X11: =(J11/I11-1)*100 -> 7.3179471 | Y11: =(K11/J11-1)*100 -> 8.6643702 | ... AB11: =(N11/M11-1)*100 -> 11.870569 | AC11: 0.02 | AD11: Flexible Sensors | AE11: 0.1375 | AF11: 0.13754545 | AG11: 0.13759091 | AH11: 0.13763636 | AI11: 0.13768182 | AJ11: 0.13772727 | AK11: 0.13777273 | AL11: 0.13781818 | AM11: 0.13786364 | AN11: 0.13790909 | AO11: 0.13795455 | AP11: 0.138
B12: Flexible Memory | C12: =C7*AE12 -> 587.345 | D12: =D7*AF12 -> 599.65168 | E12: =E7*AG12 -> 616.20019 | F12: =F7*AH12 -> 636.97959 | G12: =G7*AI12 -> 666.23602 | H12: =H7*AJ12 -> 701.82082 | I12: =I7*AK12 -> 743.71746 | J12: =J7*AL12 -> 798.27861 | ... N12: =N7*AP12 -> 1181.8368 | O12: =((N12/H12)^(1/7)-1)*100% -> 0.077291013 | Q12: Flexible Memory | R12: =(D12/C12-1)*100 -> 2.0953065 | S12: =(E12/D12-1)*100 -> 2.759687 | T12: =(F12/E12-1)*100 -> 3.3721841 | U12: =(G12/F12-1)*100 -> 4.5929931 | V12: =(H12/G12-1)*100 -> 5.3411699 | W12: =(I12/H12-1)*100 -> 5.9697061 | X12: =(J12/I12-1)*100 -> 7.3362739 | Y12: =(K12/J12-1)*100 -> 8.6829115 | ... AB12: =(N12/M12-1)*100 -> 11.88961 | AC12: 0.04 | AD12: Flexible Memory | AE12: 0.0905 | AF12: 0.090545455 | AG12: 0.090590909 | AH12: 0.090636364 | AI12: 0.090681818 | AJ12: 0.090727273 | AK12: 0.090772727 | AL12: 0.090818182 | AM12: 0.090863636 | AN12: 0.090909091 | AO12: 0.090954545 | AP12: 0.091
B13: Flexible Circuit | C13: =C7*AE13 -> 3017.85 | D13: =D7*AF13 -> 3081.6437 | E13: =E7*AG13 -> 3167.2628 | F13: =F7*AH13 -> 3274.6629 | G13: =G7*AI13 -> 3425.6888 | H13: =H7*AJ13 -> 3609.314 | I13: =I7*AK13 -> 3825.4711 | J13: =J7*AL13 -> 4106.8598 | ... N13: =N7*AP13 -> 6084.5114 | O13: =((N13/H13)^(1/7)-1)*100% -> 0.077457502 | Q13: Flexible Circuit | R13: =(D13/C13-1)*100 -> 2.1138787 | S13: =(E13/D13-1)*100 -> 2.7783579 | T13: =(F13/E13-1)*100 -> 3.3909441 | U13: =(G13/F13-1)*100 -> 4.6119521 | V13: =(H13/G13-1)*100 -> 5.3602419 | W13: =(I13/H13-1)*100 -> 5.9888693 | X13: =(J13/I13-1)*100 -> 7.3556612 | Y13: =(K13/J13-1)*100 -> 8.7025189 | ... AB13: =(N13/M13-1)*100 -> 11.909725 | AC13: 0.02 | AD13: Flexible Circuit | AE13: 0.465 | AF13: 0.46531818 | AG13: 0.46563636 | AH13: 0.46595455 | AI13: 0.46627273 | AJ13: 0.46659091 | AK13: 0.46690909 | AL13: 0.46722727 | AM13: 0.46754545 | AN13: 0.46786364 | AO13: 0.46818182 | AP13: 0.4685
B14: Single Sided Flex Circuit | C14: =C7*AE14 -> 746.35 | D14: =D7*AF14 -> 762.20786 | E14: =E7*AG14 -> 783.46777 | F14: =F7*AH14 -> 810.12048 | G14: =G7*AI14 -> 847.57244 | H14: =H7*AJ14 -> 893.09864 | I14: =I7*AK14 -> 946.68492 | J14: =J7*AL14 -> 1016.4268 | ... N14: =N7*AP14 -> 1506.5172 | O14: =((N14/H14)^(1/7)-1)*100% -> 0.077554487 | Q14: Single Sided Flex Circuit | R14: =(D14/C14-1)*100 -> 2.124721 | S14: =(E14/D14-1)*100 -> 2.7892548 | T14: =(F14/E14-1)*100 -> 3.4018898 | U14: =(G14/F14-1)*100 -> 4.6230107 | V14: =(H14/G14-1)*100 -> 5.3713633 | W14: =(I14/H14-1)*100 -> 6.0000406 | X14: =(J14/I14-1)*100 -> 7.36696 | Y14: =(K14/J14-1)*100 -> 8.7139426 | ... AB14: =(N14/M14-1)*100 -> 11.921434 | AC14: 0.02 | AD14: Single Sided Flex Circuit | AE14: 0.115 | AF14: 0.11509091 | AG14: 0.11518182 | AH14: 0.11527273 | AI14: 0.11536364 | AJ14: 0.11545455 | AK14: 0.11554545 | AL14: 0.11563636 | AM14: 0.11572727 | AN14: 0.11581818 | AO14: 0.11590909 | AP14: 0.116
B15: Double Sided Flex Circuit | C15: =C7*AE15 -> 655.49 | D15: =D7*AF15 -> 669.1896 | E15: =E7*AG15 -> 687.62128 | F15: =F7*AH15 -> 710.77211 | G15: =G7*AI15 -> 743.37914 | H15: =H7*AJ15 -> 783.04357 | I15: =I7*AK15 -> 829.74587 | J15: =J7*AL15 -> 890.57208 | ... N15: =N7*AP15 -> 1318.2026 | O15: =((N15/H15)^(1/7)-1)*100% -> 0.077243165 | Q15: Double Sided Flex Circuit | R15: =(D15/C15-1)*100 -> 2.0899782 | S15: =(E15/D15-1)*100 -> 2.7543292 | T15: =(F15/E15-1)*100 -> 3.3667995 | U15: =(G15/F15-1)*100 -> 4.58755 | V15: =(H15/G15-1)*100 -> 5.3356931 | W15: =(I15/H15-1)*100 -> 5.9642019 | X15: =(J15/I15-1)*100 -> 7.330704 | Y15: =(K15/J15-1)*100 -> 8.677277 | ... AB15: =(N15/M15-1)*100 -> 11.883826 | AC15: 0.03 | AD15: Double Sided Flex Circuit | AE15: 0.101 | AF15: 0.10104545 | AG15: 0.10109091 | AH15: 0.10113636 | AI15: 0.10118182 | AJ15: 0.10122727 | AK15: 0.10127273 | AL15: 0.10131818 | AM15: 0.10136364 | AN15: 0.10140909 | AO15: 0.10145455 | AP15: 0.1015
